# 错误异常处理

[参考网站：廖](https://www.runoob.com/python3/python3-errors-execptions.html)  
[参考网站：菜](https://www.liaoxuefeng.com/wiki/1016959663602400/1017598873256736)





## 一、语法错误
Python 的语法错误或者称之为解析错：SyntaxError: invalid syntax  
语法分析器指出了出错的一行，并且在最先找到的错误的位置标记了一个小小的箭头。





## 二、异常处理
即便 Python 程序的语法是正确的，在运行它的时候，也有可能发生错误。运行期检测到的错误被称为异常。

try-except...else-finally语句：  
如果一个异常在 try 子句里（或者在 except 和 else 子句里）被抛出，而又没有任何的 except 把它截住，那么这个异常会在 finally 子句执行后被抛出

![try-except...else-finally语句](https://www.runoob.com/wp-content/uploads/2019/07/try_except_else_finally.png)

```python
>>>def divide(x, y):
        try:
            result = x / y
        except ZeroDivisionError:
            print("division by zero!")
        else:
            print("result is", result)
        finally:
            print("executing finally clause")
   
>>> divide(2, 1)
result is 2.0
executing finally clause
>>> divide(2, 0)
division by zero!
executing finally clause
>>> divide("2", "1")   # 如果一个异常在 try 子句里（或者在 except 和 else 子句里）被抛出，而又没有任何的 except 把它截住，那么这个异常会在 finally 子句执行后被抛出
executing finally clause
Traceback (most recent call last):
  File "<stdin>", line 1, in ?
  File "<stdin>", line 3, in divide
TypeError: unsupported operand type(s) for /: 'str' and 'str'
```

## 三、抛出异常
Python 使用 raise 语句抛出一个指定的异常。 （需要自定义前提条件，如果条件为Ture则抛出）

raise语法格式如下：

`raise [Exception [, args [, traceback]]]`

![抛出异常](https://www.runoob.com/wp-content/uploads/2019/07/raise.png)

```python
x=10
if x>5:
    raise Exception('x不能大于5.当前x的值为：{}'.format(x))
```

只想知道这是否抛出了一个异常，并不想去处理它，那么一个简单的 raise 语句就可以再次把它抛出
```python
try:
    raise NameError('hi,there')    # 抛出异常
except NameError:
    print('发生异常时执行的代码')
    raise       # 在except执行完后再抛出异常
```



## 四、用户自定义异常

















## 五、Python3 内置异常类型的结构:


```python
BaseException
 +-- SystemExit
 +-- KeyboardInterrupt
 +-- GeneratorExit
 +-- Exception
      +-- StopIteration
      +-- StopAsyncIteration
      +-- ArithmeticError
      |    +-- FloatingPointError
      |    +-- OverflowError
      |    +-- ZeroDivisionError
      +-- AssertionError
      +-- AttributeError
      +-- BufferError
      +-- EOFError
      +-- ImportError
      |    +-- ModuleNotFoundError
      +-- LookupError
      |    +-- IndexError
      |    +-- KeyError
      +-- MemoryError
      +-- NameError
      |    +-- UnboundLocalError
      +-- OSError
      |    +-- BlockingIOError
      |    +-- ChildProcessError
      |    +-- ConnectionError
      |    |    +-- BrokenPipeError
      |    |    +-- ConnectionAbortedError
      |    |    +-- ConnectionRefusedError
      |    |    +-- ConnectionResetError
      |    +-- FileExistsError
      |    +-- FileNotFoundError
      |    +-- InterruptedError
      |    +-- IsADirectoryError
      |    +-- NotADirectoryError
      |    +-- PermissionError
      |    +-- ProcessLookupError
      |    +-- TimeoutError
      +-- ReferenceError
      +-- RuntimeError
      |    +-- NotImplementedError
      |    +-- RecursionError
      +-- SyntaxError
      |    +-- IndentationError
      |         +-- TabError
      +-- SystemError
      +-- TypeError
      +-- ValueError
      |    +-- UnicodeError
      |         +-- UnicodeDecodeError
      |         +-- UnicodeEncodeError
      |         +-- UnicodeTranslateError
      +-- Warning
           +-- DeprecationWarning
           +-- PendingDeprecationWarning
           +-- RuntimeWarning
           +-- SyntaxWarning
           +-- UserWarning
           +-- FutureWarning
           +-- ImportWarning
           +-- UnicodeWarning
           +-- BytesWarning
           +-- ResourceWarning
```



注意：
```python
try:
    foo()
except ValueError as e:
    print('ValueError')
except UnicodeError as e:
    print('UnicodeError')
```
**第二个except永远也捕获不到UnicodeError，因为UnicodeError是ValueError的子类，如果有，也被第一个except给捕获了**